<?xml version="1.0" ?>
<!-- =================================================================================== -->
<!-- |    This document was autogenerated by xacro from /home/mali/hokuyo_repo/hokuyo_plus/ros/denemeler_urdf/hokuyo_plus.xacro | -->
<!-- |    EDITING THIS FILE BY HAND IS NOT RECOMMENDED                                 | -->
<!-- =================================================================================== -->
<robot name="tama">
    <!-- * * * Link Definitions * * * -->
    <link name="taban">
        <visual>
            <origin rpy="0 0 0" xyz="0 0 0.035" />
            <geometry>
                <box size="0.0625 0.095 0.07" />
            </geometry>
            <material name="Cyan1">
                <color rgba="0 0.9 0.9 1.0" />
            </material>
        </visual>
        <inertial>
            <mass value="1" />
            <origin rpy="0 0 0" xyz="0 0 0" />
            <inertia ixx="0.01" ixy="0" ixz="0" iyy="0.01" iyz="0" izz="0.01" />
        </inertial>
    </link>
    <link name="pan_direk">
        <visual>
            <origin rpy="0 0 0" xyz="0 0 0" />
            <geometry>
                <box size="0.035 0.038 0.044" />
            </geometry>
            <material name="Yellow2">
                <color rgba="0.8 0.8 0 1.0" />
            </material>
        </visual>
        <inertial>
            <mass value="0.50" />
            <origin rpy="0 0 0" xyz="0 0 0" />
            <inertia ixx="0.01" ixy="0" ixz="0" iyy="0.01" iyz="0" izz="0.01" />
        </inertial>
    </link>
    <link name="tilt_direk">
        <visual>
            <origin rpy="0 -1.57 0" xyz="-0.022 0 0" />
            <geometry>
                <box size="0.005 0.005 0.044" />
            </geometry>
            <material name="Cyan1">
                <color rgba="0 0.9 0.9 1.0" />
            </material>
        </visual>
        <inertial>
            <mass value="0.20" />
            <origin rpy="0 0 0" xyz="0 0 0" />
            <inertia ixx="0.01" ixy="0" ixz="0" iyy="0.01" iyz="0" izz="0.01" />
        </inertial>
    </link>
    <link name="hokuyo_taban">
        <visual>
            <origin rpy="0 -1.57 0" xyz="0 0 0" />
            <geometry>
                <box size="0.13 0.06 0.003 " />
            </geometry>
            <material name="Yellow2">
                <color rgba="0.8 0.8 0 1.0" />
            </material>
        </visual>
        <inertial>
            <mass value="0.10" />
            <origin rpy="0 0 0" xyz="0 0 0" />
            <inertia ixx="0.01" ixy="0" ixz="0" iyy="0.01" iyz="0" izz="0.01" />
        </inertial>
    </link>
    <link name="hokuyo_link">
        <collision>
            <origin rpy="0 0 0" xyz="0 0 -0.05" />
            <geometry>
                <box size="0.1 0.1 0.08" />
            </geometry>
        </collision>
        <visual>
            <origin rpy="0 0 0" xyz="-0.035 0 0" />
            <geometry>
                <box size="0.07 0.05 0.05" />
            </geometry>
            <material name="Cyan1">
                <color rgba="0 0.9 0.9 1.0" />
            </material>
        </visual>
        <inertial>
            <mass value="1e-5" />
            <origin rpy="0 0 0" xyz="0 0 0" />
            <inertia ixx="1e-6" ixy="0" ixz="0" iyy="1e-6" iyz="0" izz="1e-6" />
        </inertial>
    </link>
    <joint name="pan_joint" type="revolute">
        <parent link="taban" />
        <child link="pan_direk" />
        <origin rpy="0 0 0" xyz="0 -0.0285 0.092" />
        <dynamics damping="1.0" />
        <axis xyz="0 0 1" />
        <limit effort="10" lower="-3.1416" upper="3.1416" velocity="3" />
    </joint>
    <joint name="tilt_joint" type="revolute">
        <parent link="pan_direk" />
        <child link="tilt_direk" />
        <origin rpy="0 1.57 0" xyz="0 0 0.022" />
        <axis xyz="0 0 1" />
        <limit effort="10" lower="-0.8727" upper="0.8727" velocity="3" />
        <dynamics damping="1.0" />
    </joint>
    <joint name="hokuyo_base_joint" type="fixed">
        <parent link="tilt_direk" />
        <child link="hokuyo_taban" />
        <origin rpy="0 0 0" xyz="-0.0450 0 0" />
        <dynamics damping="1.0" />
    </joint>
    <joint name="hokuyo_joint" type="fixed">
        <origin rpy="0 0 0" xyz="0 0 0.04" />
        <parent link="hokuyo_taban" />
        <child link="hokuyo_link" />
        <dynamics damping="1.0" />
    </joint>
    <gazebo reference="taban">
                <material>Gazebo/Orange</material>
                <turnGravityOff>true</turnGravityOff>
        </gazebo>
        
        <gazebo reference="pan_direk">
                <material>Gazebo/Blue</material>
                <turnGravityOff>true</turnGravityOff>
                
        </gazebo>
        
        <gazebo reference="tilt_direk">
                <material>Gazebo/White</material>
                <turnGravityOff>true</turnGravityOff>
        </gazebo>
        
        <gazebo reference="hokuyo_taban">
                <material>Gazebo/Orange</material>
                <turnGravityOff>true</turnGravityOff>
        </gazebo>
    <!-- gazebo reference for hokuyo-->
    <gazebo reference="hokuyo_link">
    	<material>Gazebo/Blue</material>
        <sensor name="hokuyo_sensor" type="ray">
            <pose>0 0 0 0 0 0</pose>
            <update_rate>10</update_rate>
            <ray>
                <scan>
                    <horizontal>
                        <samples>640</samples>
                        <resolution>1</resolution>
                        <min_angle>-2.094</min_angle>
                        <max_angle>2.094</max_angle>
                    </horizontal>
                </scan>
                <range>
                    <min>0.02</min>
                    <max>4.0</max>
                    <resolution>0.00628318531</resolution>
                </range>
                <noise>
                    <type>gaussian</type>
                    <mean>0.0</mean>
                    <stddev>0.0001</stddev>
                </noise>
            </ray>
            <plugin filename="libgazebo_ros_laser.so" name="body_controller">
                <topicName>hokuyo/scan</topicName>
                <frameName>hokuyo_link</frameName>
         </plugin>
        </sensor>
        <turnGravityOff>true</turnGravityOff>
    </gazebo>
    <transmission name="trans_pan_joint">
        <type>transmission_interface/SimpleTransmission</type>
        <joint name="pan_joint">
            <hardwareInterface>hardware_interface/EffortJointInterface</hardwareInterface>
        </joint>
        <actuator name="pan_joint_motor">
            <hardwareInterface>hardware_interface/EffortJointInterface</hardwareInterface>
            <mechanicalReduction>1</mechanicalReduction>
        </actuator>
    </transmission>
    <transmission name="trans_tilt_joint">
        <type>transmission_interface/SimpleTransmission</type>
        <joint name="tilt_joint">
            <hardwareInterface>hardware_interface/EffortJointInterface</hardwareInterface>
        </joint>
        <actuator name="tilt_joint_motor">
            <hardwareInterface>hardware_interface/EffortJointInterface</hardwareInterface>
            <mechanicalReduction>1</mechanicalReduction>
        </actuator>
    </transmission>
    <gazebo>
            <plugin name="gazebo_ros_control" filename="libgazebo_ros_control.so">
            </plugin>
     </gazebo>
  <material name="black">
    <color rgba="0.0 0.0 0.0 1.0"/>
  </material>
  <material name="blue">
    <color rgba="0.203125 0.23828125 0.28515625 1.0"/>
  </material>
  <material name="green">
    <color rgba="0.0 0.8 0.0 1.0"/>
  </material>
  <material name="grey">
    <color rgba="0.2 0.2 0.2 1.0"/>
  </material>
  <material name="orange">
    <color rgba="1.0 0.423529411765 0.0392156862745 1.0"/>
  </material>
  <material name="brown">
    <color rgba="0.870588235294 0.811764705882 0.764705882353 1.0"/>
  </material>
  <material name="red">
    <color rgba="0.80078125 0.12890625 0.1328125 1.0"/>
  </material>
  <material name="white">
    <color rgba="1.0 1.0 1.0 1.0"/>
  </material>
  <link name="link_chassis">
    <!-- pose and inertial -->
    <pose>0 0 0.1 0 0 0</pose>
    <inertial>
      <mass value="2"/>
      <origin rpy="0 0 0" xyz="0 0 0"/>
      <inertia ixx="0.0395416666667" ixy="0" ixz="0" iyy="0.106208333333" iyz="0" izz="0.106208333333"/>
    </inertial>
    <!-- body -->
    <collision name="collision_chassis">
      <origin rpy="0 0 0" xyz="0 0 -0.05"/>
      <geometry>
        <box size="0.3 0.3 0.3"/>
      </geometry>
    </collision>
    <visual name="visual_chassis">
      <origin rpy="0 0 0" xyz="0 0 -0.05"/>
      <geometry>
        <mesh filename = "package://hokuyo_plus/config/minik1.dae" scale="0.5 0.5 0.5"/>
      </geometry>

      <!-- <material name="blue"/>-->
    </visual>
    <!-- caster front-->
    <collision name="caster_front_collision">
      <origin rpy=" 0 0 0" xyz="0.13 0 -0.22"/>
      <geometry>
        <sphere radius="0.03"/>
      </geometry>
      <surface>
        <friction>
          <ode>
            <mu>0</mu>
            <mu2>0</mu2>
            <slip1>1.0</slip1>
            <slip2>1.0</slip2>
          </ode>
        </friction>
      </surface>
    </collision>
    <visual name="caster_front_visual">
      <origin rpy=" 0 0 0" xyz="0.13 0 -0.22"/>
      <geometry>
        <sphere radius="0.03"/>
      </geometry>
    </visual>

   <!-- caster back-->
    <collision name="caster_back_collision">
      <origin rpy=" 0 0 0" xyz="-0.13 0 -0.22"/>
      <geometry>
        <sphere radius="0.03"/>
      </geometry>
      <surface>
        <friction>
          <ode>
            <mu>0</mu>
            <mu2>0</mu2>
            <slip1>1.0</slip1>
            <slip2>1.0</slip2>
          </ode>
        </friction>
      </surface>
    </collision>
    <visual name="caster_back_visual">
      <origin rpy=" 0 0 0" xyz="-0.13 0 -0.22"/>
      <geometry>
        <sphere radius="0.03"/>
      </geometry>
    </visual>
  </link>


   <joint name="joint_sensor_laser" type="fixed">
   <origin xyz="0.1 0 0.1" rpy="0 0 0"/>
   <parent link="link_chassis"/>
   <child link="taban"/>
 </joint>

<gazebo reference="link_chassis">
    <material>Gazebo/Orange</material>
  </gazebo>
  <gazebo reference="link_left_wheel">
    <material>Gazebo/Green</material>
  </gazebo>
  <gazebo reference="link_right_wheel">
    <material>Gazebo/Blue</material>
  </gazebo>

  <gazebo reference="link_sensor_laser">
    <material>Gazebo/Blue</material>
  </gazebo>

  <gazebo>
    <plugin filename="libgazebo_ros_diff_drive.so" name="differential_drive_controller">
      <legacyMode>false</legacyMode>
      <alwaysOn>true</alwaysOn>
      <updateRate>20</updateRate>
      <leftJoint>joint_left_wheel</leftJoint>
      <rightJoint>joint_right_wheel</rightJoint>
      <wheelSeparation>0.4</wheelSeparation><!-- 0.2-->
      <wheelDiameter>0.12</wheelDiameter><!-- 0.2-->
      <wheelTorque>0.5</wheelTorque>
      <torque>0.1</torque><!-- 0.1-->
      <commandTopic>cmd_vel</commandTopic>
      <odometryTopic>odom</odometryTopic>
      <odometryFrame>odom</odometryFrame>
      <robotBaseFrame>link_chassis</robotBaseFrame>
      <publishWheelTF>true</publishWheelTF>
      <publishOdomTF>true</publishOdomTF>
      <publishWheelJointState>true</publishWheelJointState>
      <rosDebugLevel>na</rosDebugLevel>
      <publishTf>1</publishTf>
      <odometrySource>world</odometrySource>
      <wheelAcceleration>1</wheelAcceleration>
      <robotNamespace>minik0</robotNamespace>
    </plugin>
  </gazebo>
  <link name="link_right_wheel">
            <inertial>
              <mass value="0.2"/>
              <origin rpy="0 1.5707 1.5707" xyz="0 0 0"/>
              <inertia ixx="0.000526666666667" ixy="0" ixz="0" iyy="0.000526666666667" iyz="0" izz="0.001"/>
            </inertial>
            <collision name="link_right_wheel_collision">
              <origin rpy="0 1.5707 1.5707" xyz="0 0 0"/>
              <geometry>
                <cylinder length="0.04" radius="0.06"/><!-- radius="0.07-->
              </geometry>
            </collision>
            <visual name="$link_right_wheel_visual">
              <origin rpy="0 1.5707 1.5707" xyz="0 0 0"/>
              <geometry>
                <cylinder length="0.04" radius="0.06"/><!-- radius="0.07-->
              </geometry>
            </visual>
   </link>
  <link name="link_left_wheel">
            <inertial>
              <mass value="0.2"/>
              <origin rpy="0 1.5707 1.5707" xyz="0 0 0"/>
              <inertia ixx="0.000526666666667" ixy="0" ixz="0" iyy="0.000526666666667" iyz="0" izz="0.001"/>
            </inertial>
            <collision name="link_left_wheel_collision">
              <origin rpy="0 1.5707 1.5707" xyz="0 0 0"/>
              <geometry>
                <cylinder length="0.04" radius="0.06"/><!-- radius="0.07-->
              </geometry>
            </collision>
            <visual name="$link_left_wheel_visual">
              <origin rpy="0 1.5707 1.5707" xyz="0 0 0"/>
              <geometry>
                <cylinder length="0.04" radius="0.06"/><!-- radius="0.07-->
              </geometry>
            </visual>
  </link>
  <joint name="joint_right_wheel" type="continuous">
        <origin rpy="0 0 0" xyz="0 -0.2 -0.19"/>
        <child link="link_right_wheel"/>
        <parent link="link_chassis"/>
        <axis rpy="0 0 0" xyz="0 1 0"/>
        <limit effort="10000" velocity="1000"/>
        <joint_properties damping="1.0" friction="1.0"/>
      </joint>
  <joint name="joint_left_wheel" type="continuous">
        <origin rpy="0 0 0" xyz="0 0.2 -0.19"/>
        <child link="link_left_wheel"/>
        <parent link="link_chassis"/>
        <axis rpy="0 0 0" xyz="0 1 0"/>
        <limit effort="10000" velocity="1000"/>
        <joint_properties damping="1.0" friction="1.0"/>
      </joint>
</robot>

