<?xml version="1.0" ?>
<robot name="follower" xmlns:xacro="http://ros.org/wiki/xacro">
  
    <link name="base_footprint">
    <visual>
      <origin xyz="0 0 0" rpy="0 0 0" />
      <geometry>
        <box size="0.001 0.001 0.001" />
      </geometry>
    </visual>

    <collision>
      <origin xyz="0 0 0.017" rpy="0 0 0" />
      <geometry>
        <box size="0.001 0.001 0.001" />
      </geometry>
    </collision>
    </link>

    <link name="base_link">
    <inertial>
      <mass value="2" />
      <origin xyz="0 0 0.0" />
      <inertia ixx="0.01" ixy="0.0" ixz="0.0" iyy="0.01" iyz="0.0" izz="0.5" />
    </inertial>

    <visual>
      <origin xyz=" 0 0 0.0308" rpy="0 0 0" />
      <geometry>
        <mesh filename="package://gazebo_sim/meshes/create_1.dae" />
      </geometry>
    </visual>

    <collision>
      <origin xyz="0.0 0.0 0.0308" rpy="0 0 0" />
      <geometry>
        <cylinder length="0.0611632" radius="0.16495" />
      </geometry>
    </collision>
    </link>

    <link name="wall_sensor_link">
    <inertial>
      <mass value="0.01" />
      <origin xyz="0 0 0" />
      <inertia ixx="0.001" ixy="0.0" ixz="0.0" iyy="0.001" iyz="0.0" izz="0.001" />
    </inertial>
    </link>

    <link name="left_cliff_sensor_link">
    <inertial>
      <mass value="0.01" />
      <origin xyz="0 0 0" />
      <inertia ixx="0.001" ixy="0.0" ixz="0.0" iyy="0.001" iyz="0.0" izz="0.001" />
    </inertial>
    </link>

    <link name="right_cliff_sensor_link">
    <inertial>
      <mass value="0.01" />
      <origin xyz="0 0 0" />
      <inertia ixx="0.001" ixy="0.0" ixz="0.0" iyy="0.001" iyz="0.0" izz="0.001" />
    </inertial>
    </link>

    <link name="leftfront_cliff_sensor_link">
    <inertial>
      <mass value="0.01" />
      <origin xyz="0 0 0" />
      <inertia ixx="1.0" ixy="0.0" ixz="0.0" iyy="0.01" iyz="0.0" izz="0.01" />
    </inertial>
    </link>

    <link name="rightfront_cliff_sensor_link">
    <inertial>
      <mass value="0.01" />
      <origin xyz="0 0 0" />
      <inertia ixx="0.001" ixy="0.0" ixz="0.0" iyy="0.001" iyz="0.0" izz="0.001" />
    </inertial>
    </link>

    <joint name="base_footprint_joint" type="fixed">
      <origin xyz="0 0 0.017" rpy="0 0 0" />
      <parent link="base_footprint" />
      <child link="base_link" />
    </joint>

    <joint name="base_wall_sensor_joint" type="fixed">
      <origin xyz="0.09 -0.120 0.042" rpy="0 0 -1.0" />
      <parent link="base_link" />
      <child link="wall_sensor_link" />
    </joint>

    <joint name="base_left_cliff_sensor_joint" type="fixed">
      <origin xyz="0.07 0.14 0.01" rpy="0 1.57 0" />
      <parent link="base_link" />
      <child link="left_cliff_sensor_link" />
    </joint>

    <joint name="base_right_cliff_sensor_joint" type="fixed">
      <origin xyz="0.07 -0.14 0.01" rpy="0 1.57 0" />
      <parent link="base_link" />
      <child link="right_cliff_sensor_link" />
    </joint>

    <joint name="base_leftfront_cliff_sensor_joint" type="fixed">
      <origin xyz="0.15 0.04 0.01" rpy="0 1.57 0" />
      <parent link="base_link" />
      <child link="leftfront_cliff_sensor_link" />
    </joint>

    <joint name="base_rightfront_cliff_sensor_joint" type="fixed">
      <origin xyz="0.15 -0.04 0.01" rpy="0 1.57 0" />
      <parent link="base_link" />
      <child link="rightfront_cliff_sensor_link" />
    </joint>

    <!--left wheel-->
    <link name="left_wheel_link">
    <inertial>
      <origin xyz="0 0 0" />
      <mass value="0.01" />
      <inertia ixx="0.001" ixy="0.0" ixz="0.0" iyy="0.001" iyz="0.0" izz="0.001" />
    </inertial>

    <visual>
      <origin xyz="0 0 0" rpy="0 1.57 1.57" />
      <geometry>
        <cylinder radius="0.036" length="0.024" />
      </geometry>
    </visual>

    <collision>
      <origin xyz="0 0 0" rpy="0 1.57 1.57" />
      <geometry>
        <cylinder radius="0.036" length="0.024" />
      </geometry>
    </collision>
    </link>

   <joint name="left_wheel_joint" type="continuous">
      <origin xyz="0 0.13 0.015" rpy="0 0 0" />
      <parent link="base_link" />
      <child link="left_wheel_link" />
      <axis xyz="0 1 0" />
    </joint>
    
    <!--left wheel-->
    <link name="right_wheel_link">
    <inertial>
      <origin xyz="0 0 0" />
      <mass value="0.01" />
      <inertia ixx="0.001" ixy="0.0" ixz="0.0" iyy="0.001" iyz="0.0" izz="0.001" />
    </inertial>

    <visual>
      <origin xyz="0 0 0" rpy="0 1.57 1.57" />
      <geometry>
        <cylinder radius="0.036" length="0.024" />
      </geometry>
    </visual>

    <collision>
      <origin xyz="0 0 0" rpy="0 1.57 1.57" />
      <geometry>
        <cylinder radius="0.036" length="0.024" />
      </geometry>
    </collision>
    </link>

   <joint name="right_wheel_joint" type="continuous">
      <origin xyz="0 -0.13 0.015" rpy="0 0 0" />
      <parent link="base_link" />
      <child link="right_wheel_link" />
      <axis xyz="0 1 0" />
    </joint>
    
    
    <!-- end of wheels-->
    <link name="rear_wheel_link">
    <inertial>
      <origin xyz="0 0 0"/>
      <mass value="0.001" />
      <inertia ixx="0.0001" ixy="0.0" ixz="0.0"
        iyy="0.0001" iyz="0.0" izz="0.0001" />
    </inertial>

    <visual>
      <origin xyz="0 0 0" rpy="0 1.57 1.57"/>
      <geometry>
        <sphere radius="0.015" />
      </geometry>
    </visual>

    <collision>
      <origin xyz="0 0 0" rpy="0 1.57 1.57" />
      <geometry>
        <sphere radius="0.015" />
      </geometry>
    </collision>
    </link>
    <joint name="rear_castor_joint" type="fixed">
      <origin xyz="-0.13 0 0.0" rpy="0 0 0"/>
      <parent link="base_link"/>
      <child link="rear_wheel_link"/>
      <axis xyz="0 1 0"/>
    </joint>

    <link name="front_wheel_link">
    <inertial>
      <origin xyz="0 0 0" />
      <mass value="0.01" />
      <inertia ixx="0.001" ixy="0.0" ixz="0.0" iyy="0.001" iyz="0.0" izz="0.001" />
    </inertial>

    <visual>
      <origin xyz="0 0 0" rpy="0 1.57 1.57" />
      <geometry>
        <sphere radius="0.018" />
      </geometry>
    </visual>

    <collision>
      <origin xyz="0 0 0" rpy="0 1.57 1.57" />
      <geometry>
        <sphere radius="0.018" />
      </geometry>
    </collision>
    </link>

    <!-- fixed because there's no transmission -->
    <joint name="front_castor_joint" type="fixed">
      <origin xyz="0.13 0 0.0" rpy="0 0 0" />
      <parent link="base_link" />
      <child link="front_wheel_link" />
      <axis xyz="0 1 0" />
    </joint>

    <joint name="gyro_joint" type="fixed">
      <axis xyz="0 1 0" />
      <origin xyz="0 0 0.04" rpy="0 0 0" />
      <parent link="base_link" />
      <child link="gyro_link" />
    </joint>
    <link name="gyro_link">
    <inertial>
      <mass value="0.001" />
      <origin xyz="0 0 0" rpy="0 0 0" />
      <inertia ixx="0.0001" ixy="0" ixz="0" iyy="0.000001" iyz="0" izz="0.0001" />
    </inertial>
    </link>
    
    <gazebo>
      <plugin name="differential_drive_controller" filename="libgazebo_ros_diff_drive.so">
        <alwaysOn>true</alwaysOn>
        <updateRate>40</updateRate>
        <leftJoint>left_wheel_joint</leftJoint>
        <rightJoint>right_wheel_joint</rightJoint>
        <wheelSeparation>0.26</wheelSeparation>
        <wheelDiameter>0.072</wheelDiameter>
        <wheelTorque>1</wheelTorque>
        <commandTopic>cmd_vel</commandTopic>
        <odometryTopic>odom</odometryTopic>
        <odometryFrame>odom</odometryFrame>
        <robotBaseFrame>base_footprint</robotBaseFrame>
      </plugin>

      <plugin name="p3d_base_controller" filename="libgazebo_ros_p3d.so">
        <alwaysOn>true</alwaysOn>
        <updateRate>100.0</updateRate>
        <bodyName>base_link</bodyName>
        <topicName>simple_controller/absolute_position</topicName>
        <gaussianNoise>0</gaussianNoise>
        <frameName>map</frameName>
        <xyzOffsets>0 0 0</xyzOffsets>
        <rpyOffsets>0 0 0</rpyOffsets>
        <!--<interface:position name="p3d_base_position"/>-->
      </plugin>
    </gazebo>

    <gazebo reference="left_wheel_link">
      <mu1>1.0</mu1>
      <mu2>1.0</mu2>
      <kp>1000000.0</kp>
      <kd>100.0</kd>
      <minDepth>0.001</minDepth>
      <maxVel>1.0</maxVel>
    </gazebo>

    <gazebo reference="right_wheel_link">
      <mu1>1.0</mu1>
      <mu2>1.0</mu2>
      <kp>1000000.0</kp>
      <kd>100.0</kd>
      <minDepth>0.001</minDepth>
      <maxVel>1.0</maxVel>
    </gazebo>
    <gazebo reference="rear_wheel_link">
      <mu1>0.0</mu1>
      <mu2>0.0</mu2>
      <kp>1000000.0</kp>
      <kd>100.0</kd>
      <minDepth>0.001</minDepth>
      <maxVel>1.0</maxVel>
    </gazebo>

    <gazebo reference="front_wheel_link">
      <mu1>0.0</mu1>
      <mu2>0.0</mu2>
      <kp>1000000.0</kp>
      <kd>100.0</kd>
      <minDepth>0.001</minDepth>
      <maxVel>1.0</maxVel>
    </gazebo>

    <gazebo>
      <plugin name="imu_controller" filename="libgazebo_ros_imu.so">
        <alwaysOn>true</alwaysOn>
        <updateRate>30</updateRate>
        <bodyName>gyro_link</bodyName>
        <topicName>follower/imu/data</topicName>
        <serviceName>follower/imu/is_calibrated</serviceName>
        <gaussianNoise>0.00000289</gaussianNoise>
        <xyzOffsets>0 0 0</xyzOffsets>
        <rpyOffsets>0 0 0</rpyOffsets>
      </plugin>
    </gazebo>
  

    <gazebo reference="wall_sensor_link">
      <sensor type="ray" name="wall_sensor">
        <always_on>true</always_on>
        <update_rate>20.0</update_rate>
        <pose>0 0 0 0 0 0</pose>
        <visualize>false</visualize>
        <ray>
          <scan>
            <horizontal>
              <samples>1</samples>
              <resolution>1</resolution>
              <min_angle>0</min_angle>
              <max_angle>0</max_angle>
            </horizontal>
          </scan>
          <range>
            <min>0.0160</min>
            <max>0.04</max>
            <resolution>0.1</resolution>
          </range>
        </ray>
      </sensor>
    </gazebo>

 
    <gazebo reference="left_cliff_sensor_link">
      <sensor type="ray" name="left_cliff_sensor">
        <always_on>true</always_on>
        <update_rate>20.0</update_rate>
        <pose>0 0 0 0 0 0</pose>
        <visualize>false</visualize>
        <ray>
          <scan>
            <horizontal>
              <samples>1</samples>
              <resolution>1</resolution>
              <min_angle>0</min_angle>
              <max_angle>0</max_angle>
            </horizontal>
          </scan>
          <range>
            <min>0.01</min>
            <max>0.04</max>
            <resolution>0.1</resolution>
          </range>
        </ray>
      </sensor>
    </gazebo>

    <gazebo reference="right_cliff_sensor_link">
      <sensor type="ray" name="right_cliff_sensor">
        <always_on>true</always_on>
        <update_rate>20.0</update_rate>
        <pose>0 0 0 0 0 0</pose>
        <visualize>false</visualize>
        <ray>
          <scan>
            <horizontal>
              <samples>1</samples>
              <resolution>1</resolution>
              <min_angle>0</min_angle>
              <max_angle>0</max_angle>
            </horizontal>
          </scan>
          <range>
            <min>0.01</min>
            <max>0.04</max>
            <resolution>0.1</resolution>
          </range>
        </ray>
      </sensor>
    </gazebo>

    <gazebo reference="leftfront_cliff_sensor_link">
      <sensor type="ray" name="leftfront_cliff_sensor">
        <always_on>true</always_on>
        <update_rate>20.0</update_rate>
        <pose>0 0 0 0 0 0</pose>
        <visualize>false</visualize>
        <ray>
          <scan>
            <horizontal>
              <samples>1</samples>
              <resolution>1</resolution>
              <min_angle>0</min_angle>
              <max_angle>0</max_angle>
            </horizontal>
          </scan>
          <range>
            <min>0.01</min>
            <max>0.04</max>
            <resolution>0.1</resolution>
          </range>
        </ray>
      </sensor>
    </gazebo>

    <gazebo reference="rightfront_cliff_sensor_link">
      <sensor type="ray" name="rightfront_cliff_sensor">
        <always_on>true</always_on>
        <update_rate>20.0</update_rate>
        <pose>0 0 0 0 0 0</pose>
        <visualize>false</visualize>
        <ray>
          <scan>
            <horizontal>
              <samples>1</samples>
              <resolution>1</resolution>
              <min_angle>0</min_angle>
              <max_angle>0</max_angle>
            </horizontal>
          </scan>
          <range>
            <min>0.01</min>
            <max>0.04</max>
            <resolution>0.1</resolution>
          </range>
        </ray>
      </sensor>
    </gazebo>
    <!--circles-->
    <!-- part1-->
    <joint name="spacer_0_joint" type="fixed">
      <origin xyz="-0.00254 0.1114679 0.062992" rpy="0 0 0" />
      <parent link="base_link"/>
      <child link="spacer_0_link" />
    </joint>

    <link name="spacer_0_link">
      <inertial>
        <mass value="0.001" />
        <origin xyz="0 0 0" />
        <inertia ixx="0.0001" ixy="0.0" ixz="0.0"
          iyy="0.0001" iyz="0.0"
          izz="0.0001" />
      </inertial>

      <visual>
        <origin xyz=" 0 0 0 " rpy="0 0 0" />
        <geometry>
          <mesh filename="package://gazebo_sim/meshes/stacks/circles/68-02403-125_Spacer.dae"/>
        </geometry>
      </visual>

      <collision>
        <origin xyz="0.0 0.0 0.0" rpy="0 0 0" />
        <geometry>
          <cylinder length="0.003175" radius=".0127"/>
        </geometry>
      </collision>
    </link>

    <!-- part2-->
    <joint name="spacer_1_joint" type="fixed">
      <origin xyz="-0.00254 -0.1114679 0.062992" rpy="0 0 0" />
      <parent link="base_link"/>
      <child link="spacer_1_link" />
    </joint>

    <link name="spacer_1_link">
      <inertial>
        <mass value="0.001" />
        <origin xyz="0 0 0" />
        <inertia ixx="0.0001" ixy="0.0" ixz="0.0"
          iyy="0.0001" iyz="0.0"
          izz="0.0001" />
      </inertial>

      <visual>
        <origin xyz=" 0 0 0 " rpy="0 0 0" />
        <geometry>
          <mesh filename="package://gazebo_sim/meshes/stacks/circles/68-02403-125_Spacer.dae"/>
        </geometry>
      </visual>

      <collision>
        <origin xyz="0.0 0.0 0.0" rpy="0 0 0" />
        <geometry>
          <cylinder length="0.003175" radius=".0127"/>
        </geometry>
      </collision>
    </link>

    <!-- part3-->
    <joint name="spacer_2_joint" type="fixed">
      <origin xyz="-0.07239 -0.1114679 0.062992" rpy="0 0 0" />
      <parent link="base_link"/>
      <child link="spacer_2_link" />
    </joint>

    <link name="spacer_2_link">
      <inertial>
        <mass value="0.001" />
        <origin xyz="0 0 0" />
        <inertia ixx="0.0001" ixy="0.0" ixz="0.0"
          iyy="0.0001" iyz="0.0"
          izz="0.0001" />
      </inertial>

      <visual>
        <origin xyz=" 0 0 0 " rpy="0 0 0" />
        <geometry>
          <mesh filename="package://gazebo_sim/meshes/stacks/circles/68-02403-125_Spacer.dae"/>
        </geometry>
      </visual>

      <collision>
        <origin xyz="0.0 0.0 0.0" rpy="0 0 0" />
        <geometry>
          <cylinder length="0.003175" radius=".0127"/>
        </geometry>
      </collision>
    </link>
 
    <!-- part4-->
    <joint name="spacer_3_joint" type="fixed">
      <origin xyz="-0.07239 0.1114679 0.062992" rpy="0 0 0" />
      <parent link="base_link"/>
      <child link="spacer_3_link" />
    </joint>

    <link name="spacer_3_link">
      <inertial>
        <mass value="0.001" />
        <origin xyz="0 0 0" />
        <inertia ixx="0.0001" ixy="0.0" ixz="0.0"
          iyy="0.0001" iyz="0.0"
          izz="0.0001" />
      </inertial>

      <visual>
        <origin xyz=" 0 0 0 " rpy="0 0 0" />
        <geometry>
          <mesh filename="package://gazebo_sim/meshes/stacks/circles/68-02403-125_Spacer.dae"/>
        </geometry>
      </visual>

      <collision>
        <origin xyz="0.0 0.0 0.0" rpy="0 0 0" />
        <geometry>
          <cylinder length="0.003175" radius=".0127"/>
        </geometry>
      </collision>
    </link>
    <!--end parts-->
    
    <joint name="plate_0_joint" type="fixed">
      <origin xyz="-0.04334 0  0.06775704" rpy="0 0 0" />
      <parent link="base_link"/>
      <child link="plate_0_link" />
    </joint>


    <link name="plate_0_link">
      <inertial>
        <mass value="0.01" />
        <origin xyz="0 0 0" />
        <inertia ixx="0.01" ixy="0.0" ixz="0.0"
          iyy="0.01" iyz="0.0"
          izz="0.01" />
      </inertial>
  
      <visual>
        <origin xyz=" 0 0 0 " rpy="0 0 0" />
        <geometry>
          <mesh filename="package://gazebo_sim/meshes/stacks/circles/plate_0_logo.dae"/>
        </geometry>
      </visual>

      <collision>
        <origin xyz="0.0 0.0 0.0" rpy="0 0 0" />
        <geometry>
          <box size="0.233502 0.314845 0.006401"/>
        </geometry>
      </collision>
    </link>


    <!--standoff1-->
    <joint name="standoff_2in_0_joint" type="fixed">
      <origin xyz="0.0676402 0.1314196 0.0709803" rpy="0 0 0" />
      <parent link="base_link"/>
      <child link="standoff_2in_0_link" />
    </joint>

    <link name="standoff_2in_0_link">
      <inertial>
        <mass value="0.001" />
        <origin xyz="0 0 0" />
        <inertia ixx="0.0001" ixy="0.0" ixz="0.0"
          iyy="0.0001" iyz="0.0"
          izz="0.0001" />
      </inertial>

      <visual>
        <origin xyz=" 0 0 0 " rpy="0 0 0" />
        <geometry>
          <mesh filename="package://gazebo_sim/meshes/stacks/circles/68-04552-2000-RA_Turtlebot_M-F_Standoff.dae"/>
        </geometry>
      </visual>

      <collision>
        <origin xyz="0.0 0.0 0.0" rpy="0 0 0" />
        <geometry>
          <cylinder length="0.0635" radius="0.0381"/>
        </geometry>
      </collision>
    </link>

    <!--standoff2-->
    <joint name="standoff_2in_1_joint" type="fixed">
      <origin xyz="0.0676402 -0.1314196 0.0709803" rpy="0 0 0" />
      <parent link="base_link"/>
      <child link="standoff_2in_1_link" />
    </joint>

    <link name="standoff_2in_1_link">
      <inertial>
        <mass value="0.001" />
        <origin xyz="0 0 0" />
        <inertia ixx="0.0001" ixy="0.0" ixz="0.0"
          iyy="0.0001" iyz="0.0"
          izz="0.0001" />
      </inertial>

      <visual>
        <origin xyz=" 0 0 0 " rpy="0 0 0" />
        <geometry>
          <mesh filename="package://gazebo_sim/meshes/stacks/circles/68-04552-2000-RA_Turtlebot_M-F_Standoff.dae"/>
        </geometry>
      </visual>

      <collision>
        <origin xyz="0.0 0.0 0.0" rpy="0 0 0" />
        <geometry>
          <cylinder length="0.0635" radius="0.0381"/>
        </geometry>
      </collision>
    </link>

    <!--standoff3-->
    <joint name="standoff_2in_2_joint" type="fixed">
      <origin xyz="-0.052832 -0.1314196 0.0709803" rpy="0 0 0" />
      <parent link="base_link"/>
      <child link="standoff_2in_2_link" />
    </joint>

    <link name="standoff_2in_2_link">
      <inertial>
        <mass value="0.001" />
        <origin xyz="0 0 0" />
        <inertia ixx="0.0001" ixy="0.0" ixz="0.0"
          iyy="0.0001" iyz="0.0"
          izz="0.0001" />
      </inertial>

      <visual>
        <origin xyz=" 0 0 0 " rpy="0 0 0" />
        <geometry>
          <mesh filename="package://gazebo_sim/meshes/stacks/circles/68-04552-2000-RA_Turtlebot_M-F_Standoff.dae"/>
        </geometry>
      </visual>

      <collision>
        <origin xyz="0.0 0.0 0.0" rpy="0 0 0" />
        <geometry>
          <cylinder length="0.0635" radius="0.0381"/>
        </geometry>
      </collision>
    </link>

    <!--standoff4-->
    <joint name="standoff_2in_3_joint" type="fixed">
      <origin xyz="-0.052832 0.1314196 0.0709803" rpy="0 0 0" />
      <parent link="base_link"/>
      <child link="standoff_2in_3_link" />
    </joint>

    <link name="standoff_2in_3_link">
      <inertial>
        <mass value="0.001" />
        <origin xyz="0 0 0" />
        <inertia ixx="0.0001" ixy="0.0" ixz="0.0"
          iyy="0.0001" iyz="0.0"
          izz="0.0001" />
      </inertial>

      <visual>
        <origin xyz=" 0 0 0 " rpy="0 0 0" />
        <geometry>
          <mesh filename="package://gazebo_sim/meshes/stacks/circles/68-04552-2000-RA_Turtlebot_M-F_Standoff.dae"/>
        </geometry>
      </visual>

      <collision>
        <origin xyz="0.0 0.0 0.0" rpy="0 0 0" />
        <geometry>
          <cylinder length="0.0635" radius="0.0381"/>
        </geometry>
      </collision>
    </link>
    <!--standoffs end-->

    <joint name="plate_1_joint" type="fixed">
      <origin xyz="0.04068 0 0.05715" rpy="0 0 0" />
      <parent link="plate_0_link"/>
      <child link="plate_1_link" />
    </joint>

    <link name="plate_1_link">
      <inertial>
        <mass value="0.1" />
        <origin xyz="0 0 0" />
        <inertia ixx="0.01" ixy="0.0" ixz="0.0"
          iyy="0.01" iyz="0.0"
          izz="0.01" />
      </inertial>

      <visual>
        <origin xyz=" 0 0 0 " rpy="0 0 0" />
        <geometry>
          <mesh filename="package://gazebo_sim/meshes/stacks/circles/plate_1_logo.dae"/>
        </geometry>
      </visual>

      <collision>
        <origin xyz="0.0 0.0 0.0" rpy="0 0 0" />
        <geometry>
          <box size="0.314856 0.314856 0.006401"/>
        </geometry>
      </collision>
    </link>


    <!--standoff2_1-->
    <joint name="standoff_2in_4_joint" type="fixed">
      <origin xyz="0 0 0.05715" rpy="0 0 0" />
      <parent link="standoff_2in_0_link"/>
      <child link="standoff_2in_4_link" />
    </joint>

    <link name="standoff_2in_4_link">
      <inertial>
        <mass value="0.001" />
        <origin xyz="0 0 0" />
        <inertia ixx="0.0001" ixy="0.0" ixz="0.0"
          iyy="0.0001" iyz="0.0"
          izz="0.0001" />
      </inertial>

      <visual>
        <origin xyz=" 0 0 0 " rpy="0 0 0" />
        <geometry>
          <mesh filename="package://gazebo_sim/meshes/stacks/circles/68-04552-2000-RA_Turtlebot_M-F_Standoff.dae"/>
        </geometry>
      </visual>

      <collision>
        <origin xyz="0.0 0.0 0.0" rpy="0 0 0" />
        <geometry>
          <cylinder length="0.0635" radius="0.0381"/>
        </geometry>
      </collision>
    </link>

    <!--standoff2_2-->
    <joint name="standoff_2in_5_joint" type="fixed">
      <origin xyz="0 0 0.05715" rpy="0 0 0" />
      <parent link="standoff_2in_1_link"/>
      <child link="standoff_2in_5_link" />
    </joint>

    <link name="standoff_2in_5_link">
      <inertial>
        <mass value="0.001" />
        <origin xyz="0 0 0" />
        <inertia ixx="0.0001" ixy="0.0" ixz="0.0"
          iyy="0.0001" iyz="0.0"
          izz="0.0001" />
      </inertial>

      <visual>
        <origin xyz=" 0 0 0 " rpy="0 0 0" />
        <geometry>
          <mesh filename="package://gazebo_sim/meshes/stacks/circles/68-04552-2000-RA_Turtlebot_M-F_Standoff.dae"/>
        </geometry>
      </visual>

      <collision>
        <origin xyz="0.0 0.0 0.0" rpy="0 0 0" />
        <geometry>
          <cylinder length="0.0635" radius="0.0381"/>
        </geometry>
      </collision>
    </link>

    <!--standoff2_3-->
    <joint name="standoff_2in_6_joint" type="fixed">
      <origin xyz="0 0 0.05715" rpy="0 0 0" />
      <parent link="standoff_2in_2_link"/>
      <child link="standoff_2in_6_link" />
    </joint>

    <link name="standoff_2in_6_link">
      <inertial>
        <mass value="0.001" />
        <origin xyz="0 0 0" />
        <inertia ixx="0.0001" ixy="0.0" ixz="0.0"
          iyy="0.0001" iyz="0.0"
          izz="0.0001" />
      </inertial>

      <visual>
        <origin xyz=" 0 0 0 " rpy="0 0 0" />
        <geometry>
          <mesh filename="package://gazebo_sim/meshes/stacks/circles/68-04552-2000-RA_Turtlebot_M-F_Standoff.dae"/>
        </geometry>
      </visual>

      <collision>
        <origin xyz="0.0 0.0 0.0" rpy="0 0 0" />
        <geometry>
          <cylinder length="0.0635" radius="0.0381"/>
        </geometry>
      </collision>
    </link>

    <!--standoff2_4-->
    <joint name="standoff_2in_7_joint" type="fixed">
      <origin xyz="0 0 0.05715" rpy="0 0 0" />
      <parent link="standoff_2in_3_link"/>
      <child link="standoff_2in_7_link" />
    </joint>

    <link name="standoff_2in_7_link">
      <inertial>
        <mass value="0.001" />
        <origin xyz="0 0 0" />
        <inertia ixx="0.0001" ixy="0.0" ixz="0.0"
          iyy="0.0001" iyz="0.0"
          izz="0.0001" />
      </inertial>

      <visual>
        <origin xyz=" 0 0 0 " rpy="0 0 0" />
        <geometry>
          <mesh filename="package://gazebo_sim/meshes/stacks/circles/68-04552-2000-RA_Turtlebot_M-F_Standoff.dae"/>
        </geometry>
      </visual>

      <collision>
        <origin xyz="0.0 0.0 0.0" rpy="0 0 0" />
        <geometry>
          <cylinder length="0.0635" radius="0.0381"/>
        </geometry>
      </collision>
    </link>
    
    <!--standoff2 end-->

    <joint name="plate_2_joint" type="fixed">
      <origin xyz="0 0 0.0572008" rpy="0 0 0" />
      <parent link="plate_1_link"/>
      <child link="plate_2_link" />
    </joint>

    <link name="plate_2_link">
      <inertial>
        <mass value="0.01" />
        <origin xyz="0 0 0" />
        <inertia ixx="0.001" ixy="0.0" ixz="0.0"
          iyy="0.001" iyz="0.0"
          izz="0.001" />
      </inertial>

      <visual>
        <origin xyz=" 0 0 0 " rpy="0 0 0" />
        <geometry>
          <mesh filename="package://gazebo_sim/meshes/stacks/circles/plate_1_logo.dae"/>
        </geometry>
      </visual>

      <collision>
        <origin xyz="0.0 0.0 0.0" rpy="0 0 0" />
        <geometry>
          <box size="0.314856 0.314856 0.006401"/>
        </geometry>
      </collision>
    </link>

    
    <joint name="standoff_kinect_0_joint" type="fixed">
      <origin xyz="-0.1024382 0.098 0.0032004" rpy="0 0 0" />
      <parent link="plate_2_link"/>
      <child link="standoff_kinect_0_link" />
    </joint>

    <link name="standoff_kinect_0_link">
      <inertial>
        <mass value="0.001" />
        <origin xyz="0 0 0" />
        <inertia ixx="0.0001" ixy="0.0" ixz="0.0"
          iyy="0.0001" iyz="0.0"
          izz="0.0001" />
      </inertial>

      <visual>
        <origin xyz=" 0 0 0 " rpy="0 0 0" />
        <geometry>
          <mesh filename="package://gazebo_sim/meshes/stacks/circles/68-04556-RA_Kinect_Standoff_Assy.dae"/>
        </geometry>
      </visual>

      <collision>
        <origin xyz="0.0 0.0 0.0" rpy="0 0 0" />
        <geometry>
          <cylinder length="0.008585" radius="0.001111"/>
        </geometry>
      </collision>
    </link>

    <joint name="standoff_kinect_1_joint" type="fixed">
      <origin xyz="-0.1024382 -0.098 0.0032004" rpy="0 0 0" />
      <parent link="plate_2_link"/>
      <child link="standoff_kinect_1_link" />
    </joint>

    <link name="standoff_kinect_1_link">
      <inertial>
        <mass value="0.001" />
        <origin xyz="0 0 0" />
        <inertia ixx="0.0001" ixy="0.0" ixz="0.0"
          iyy="0.0001" iyz="0.0"
          izz="0.0001" />
      </inertial>

      <visual>
        <origin xyz=" 0 0 0 " rpy="0 0 0" />
        <geometry>
          <mesh filename="package://gazebo_sim/meshes/stacks/circles/68-04556-RA_Kinect_Standoff_Assy.dae"/>
        </geometry>
      </visual>

      <collision>
        <origin xyz="0.0 0.0 0.0" rpy="0 0 0" />
        <geometry>
          <cylinder length="0.008585" radius="0.001111"/>
        </geometry>
      </collision>
    </link>


    <joint name="standoff_8in_0_joint" type="fixed">
      <origin xyz="0 0 0.05715" rpy="0 0 0" />
      <parent link="standoff_2in_4_link"/>
      <child link="standoff_8in_0_link" />
    </joint>

    <link name="standoff_8in_0_link">
      <inertial>
        <mass value="0.001" />
        <origin xyz="0 0 0" />
        <inertia ixx="0.0001" ixy="0.0" ixz="0.0"
          iyy="0.0001" iyz="0.0"
          izz="0.0001" />
      </inertial>

      <visual>
        <origin xyz=" 0 0 0 " rpy="0 0 0" />
        <geometry>
          <mesh filename="package://gazebo_sim/meshes/stacks/circles/68-02421-8000-RA_Turtlebot_F-F_Standoff.dae"/>
        </geometry>
      </visual>

      <collision>
        <origin xyz="0.0 0.0 0.0" rpy="0 0 0" />
        <geometry>
          <cylinder length="0.2032" radius="0.011113"/>
        </geometry>
      </collision>
    </link>

    <joint name="standoff_8in_1_joint" type="fixed">
      <origin xyz="0 0 0.05715" rpy="0 0 0" />
      <parent link="standoff_2in_5_link"/>
      <child link="standoff_8in_1_link" />
    </joint>

    <link name="standoff_8in_1_link">
      <inertial>
        <mass value="0.001" />
        <origin xyz="0 0 0" />
        <inertia ixx="0.0001" ixy="0.0" ixz="0.0"
          iyy="0.0001" iyz="0.0"
          izz="0.0001" />
      </inertial>

      <visual>
        <origin xyz=" 0 0 0 " rpy="0 0 0" />
        <geometry>
          <mesh filename="package://gazebo_sim/meshes/stacks/circles/68-02421-8000-RA_Turtlebot_F-F_Standoff.dae"/>
        </geometry>
      </visual>

      <collision>
        <origin xyz="0.0 0.0 0.0" rpy="0 0 0" />
        <geometry>
          <cylinder length="0.2032" radius="0.011113"/>
        </geometry>
      </collision>
    </link>

    <joint name="standoff_8in_2_joint" type="fixed">
      <origin xyz="0 0 0.05715" rpy="0 0 0" />
      <parent link="standoff_2in_6_link"/>
      <child link="standoff_8in_2_link" />
    </joint>

    <link name="standoff_8in_2_link">
      <inertial>
        <mass value="0.001" />
        <origin xyz="0 0 0" />
        <inertia ixx="0.0001" ixy="0.0" ixz="0.0"
          iyy="0.0001" iyz="0.0"
          izz="0.0001" />
      </inertial>

      <visual>
        <origin xyz=" 0 0 0 " rpy="0 0 0" />
        <geometry>
          <mesh filename="package://gazebo_sim/meshes/stacks/circles/68-02421-8000-RA_Turtlebot_F-F_Standoff.dae"/>
        </geometry>
      </visual>

      <collision>
        <origin xyz="0.0 0.0 0.0" rpy="0 0 0" />
        <geometry>
          <cylinder length="0.2032" radius="0.011113"/>
        </geometry>
      </collision>
    </link>

    <joint name="standoff_8in_3_joint" type="fixed">
      <origin xyz="0 0 0.05715" rpy="0 0 0" />
      <parent link="standoff_2in_7_link"/>
      <child link="standoff_8in_3_link" />
    </joint>

    <link name="standoff_8in_3_link">
      <inertial>
        <mass value="0.001" />
        <origin xyz="0 0 0" />
        <inertia ixx="0.0001" ixy="0.0" ixz="0.0"
          iyy="0.0001" iyz="0.0"
          izz="0.0001" />
      </inertial>

      <visual>
        <origin xyz=" 0 0 0 " rpy="0 0 0" />
        <geometry>
          <mesh filename="package://gazebo_sim/meshes/stacks/circles/68-02421-8000-RA_Turtlebot_F-F_Standoff.dae"/>
        </geometry>
      </visual>

      <collision>
        <origin xyz="0.0 0.0 0.0" rpy="0 0 0" />
        <geometry>
          <cylinder length="0.2032" radius="0.011113"/>
        </geometry>
      </collision>
    </link>
    <!--end-->

    <joint name="plate_3_joint" type="fixed">
      <origin xyz="-0.01316 0 0.2063496" rpy="0 0 0" />
      <parent link="plate_2_link"/>
      <child link="plate_3_link" />
    </joint>

    <link name="plate_3_link">
      <inertial>
        <mass value="0.01" />
        <origin xyz="0 0 0" />
        <inertia ixx="0.0001" ixy="0.0" ixz="0.0"
          iyy="0.0001" iyz="0.0"
          izz="0.0001" />
      </inertial>
  
      <visual>
        <origin xyz=" 0 0 0 " rpy="0 0 0" />
        <geometry>
          <mesh filename="package://gazebo_sim/meshes/stacks/circles/plate_2_logo.dae"/>
        </geometry>
      </visual>

      <collision>
        <origin xyz="0.0 0.0 0.0" rpy="0 0 0" />
        <geometry>
          <box size="0.288 0.315 0.006401"/>
        </geometry>
      </collision>
    </link>
    <!-- end of circles-->
    
    <!--sensor hokuyo_plus-->
    <joint name="hokuyo_turtle_joint" type="fixed">
      <origin xyz="0.087 -0.0125 0.39" rpy="0 0 0"/>
      <parent link="base_link"/>
      <child link="taban" />
    </joint>
    

    <!-- * * * Link Definitions * * * -->

    <link name="taban">
        <visual>
            <origin rpy="0 0 0" xyz="0 0 0.035" />
            <geometry>
                <box size="0.0625 0.095 0.07" />
            </geometry>
            <material name="Cyan1">
                <color rgba="0 0.9 0.9 1.0" />
            </material>
        </visual>
        <inertial>
            <mass value="1" />
            <origin rpy="0 0 0" xyz="0 0 0" />
            <inertia ixx="0.01" ixy="0" ixz="0" iyy="0.01" iyz="0" izz="0.01" />
        </inertial>
    </link>
    <link name="pan_direk">
        <visual>
            <origin rpy="0 0 0" xyz="0 0 0" />
            <geometry>
                <box size="0.035 0.038 0.044" />
            </geometry>
            <material name="Yellow2">
                <color rgba="0.8 0.8 0 1.0" />
            </material>
        </visual>
        <inertial>
            <mass value="0.50" />
            <origin rpy="0 0 0" xyz="0 0 0" />
            <inertia ixx="0.01" ixy="0" ixz="0" iyy="0.01" iyz="0" izz="0.01" />
        </inertial>
    </link>
    <link name="tilt_direk">
        <visual>
            <origin rpy="0 -1.57 0" xyz="-0.022 0 0" />
            <geometry>
                <box size="0.005 0.005 0.044" />
            </geometry>
            <material name="Cyan1">
                <color rgba="0 0.9 0.9 1.0" />
            </material>
        </visual>
        <inertial>
            <mass value="0.20" />
            <origin rpy="0 0 0" xyz="0 0 0" />
            <inertia ixx="0.01" ixy="0" ixz="0" iyy="0.01" iyz="0" izz="0.01" />
        </inertial>
    </link>
    <link name="hokuyo_taban">
        <visual>
            <origin rpy="0 -1.57 0" xyz="0 0 0" />
            <geometry>
                <box size="0.13 0.06 0.003 " />
            </geometry>
            <material name="Yellow2">
                <color rgba="0.8 0.8 0 1.0" />
            </material>
        </visual>
        <inertial>
            <mass value="0.10" />
            <origin rpy="0 0 0" xyz="0 0 0" />
            <inertia ixx="0.01" ixy="0" ixz="0" iyy="0.01" iyz="0" izz="0.01" />
        </inertial>
    </link>
    <link name="hokuyo_link">
        <collision>
            <origin rpy="0 0 0" xyz="0 0 -0.05" />
            <geometry>
                <box size="0.1 0.1 0.08" />
            </geometry>
        </collision>
        <visual>
            <origin rpy="0 0 0" xyz="-0.035 0 0" />
            <geometry>
                <mesh filename="package://gazebo_sim/meshes/hokuyo/hokuyo_urg_04lx.dae"/>
            </geometry>
            <material name="Cyan1">
                <color rgba="0 0.9 0.9 1.0" />
            </material>
        </visual>
        <inertial>
            <mass value="1e-5" />
            <origin rpy="0 0 0" xyz="0 0 0" />
            <inertia ixx="1e-6" ixy="0" ixz="0" iyy="1e-6" iyz="0" izz="1e-6" />
        </inertial>
    </link>

    <joint name="pan_joint" type="revolute">
        <parent link="taban" />
        <child link="pan_direk" />
        <origin rpy="0 0 0" xyz="0 -0.0285 0.092" />
        <dynamics damping="1.0" />
        <axis xyz="0 0 1" />
        <limit effort="10" lower="-3.1416" upper="3.1416" velocity="3" />
    </joint>
    <joint name="tilt_joint" type="revolute">
        <parent link="pan_direk" />
        <child link="tilt_direk" />
        <origin rpy="0 1.57 0" xyz="0 0 0.022" />
        <axis xyz="0 0 1" />
        <limit effort="10" lower="-0.8727" upper="0.8727" velocity="3" />
        <dynamics damping="1.0" />
    </joint>
    <joint name="hokuyo_base_joint" type="fixed">
        <parent link="tilt_direk" />
        <child link="hokuyo_taban" />
        <origin rpy="0 0 0" xyz="-0.0450 0 0" />
        <dynamics damping="1.0" />
    </joint>
    <joint name="hokuyo_joint" type="fixed">
        <origin rpy="0 -1.57 0" xyz="0 0 0.075" />
        <parent link="hokuyo_taban" />
        <child link="hokuyo_link" />
        <dynamics damping="1.0" />
    </joint>
    <gazebo reference="taban">
                <material>Gazebo/Orange</material>
               
        </gazebo>
        
        <gazebo reference="pan_direk">
                <material>Gazebo/Blue</material>
                
                
        </gazebo>
        
        <gazebo reference="tilt_direk">
                <material>Gazebo/White</material>
                
        </gazebo>
        
        <gazebo reference="hokuyo_taban">
                <material>Gazebo/Orange</material>
                
    </gazebo>
    <!-- gazebo reference for hokuyo-->
    <gazebo reference="hokuyo_link">
    	<material>Gazebo/Blue</material>
        <sensor name="hokuyo_sensor" type="ray">
            <pose>0 0 0 0 0 0</pose>
            <update_rate>10</update_rate>
            <ray>
                <scan>
                    <horizontal>
                        <samples>640</samples>
                        <resolution>1</resolution>
                        <min_angle>-2.094</min_angle>
                        <max_angle>2.094</max_angle>
                    </horizontal>
                </scan>
                <range>
                    <min>0.02</min>
                    <max>4.0</max>
                    <resolution>0.00628318531</resolution>
                </range>
                <noise>
                    <type>gaussian</type>
                    <mean>0.0</mean>
                    <stddev>0.01</stddev>
                </noise>
            </ray>
            <plugin filename="libgazebo_ros_laser.so" name="body_controller">
                <topicName>hokuyo/scan</topicName>
                <frameName>hokuyo_link</frameName>
         </plugin>
        </sensor>
        <turnGravityOff>true</turnGravityOff>
    </gazebo>
    <transmission name="trans_pan_joint">
        <type>transmission_interface/SimpleTransmission</type>
        <joint name="pan_joint">
            <hardwareInterface>hardware_interface/EffortJointInterface</hardwareInterface>
        </joint>
        <actuator name="pan_joint_motor">
            <hardwareInterface>hardware_interface/EffortJointInterface</hardwareInterface>
            <mechanicalReduction>1</mechanicalReduction>
        </actuator>
    </transmission>
    <transmission name="trans_tilt_joint">
        <type>transmission_interface/SimpleTransmission</type>
        <joint name="tilt_joint">
            <hardwareInterface>hardware_interface/EffortJointInterface</hardwareInterface>
        </joint>
        <actuator name="tilt_joint_motor">
            <hardwareInterface>hardware_interface/EffortJointInterface</hardwareInterface>
            <mechanicalReduction>1</mechanicalReduction>
        </actuator>
    </transmission>
    <gazebo>
            <plugin name="gazebo_ros_control" filename="libgazebo_ros_control.so">
            </plugin>
     </gazebo>

    
    
</robot>
