<?xml version="1.0" ?>
<!-- =================================================================================== -->
<!-- |    This document was autogenerated by xacro from /home/mali/hokuyo_repo/hokuyo_plus/ros/denemeler_urdf/hokuyo_plus.xacro | -->
<!-- |    EDITING THIS FILE BY HAND IS NOT RECOMMENDED                                 | -->
<!-- =================================================================================== -->
<robot name="tama">
    <!-- * * * Link Definitions * * * -->
    <link name="world" />
    <link name="taban">
        <visual>
            <origin rpy="0 0 0" xyz="0 0 0.035" />
            <geometry>
                <box size="0.0625 0.095 0.07" />
            </geometry>
            <material name="Cyan1">
                <color rgba="0 0.9 0.9 1.0" />
            </material>
        </visual>
        <inertial>
            <mass value="1" />
            <origin rpy="0 0 0" xyz="0 0 0" />
            <inertia ixx="0.01" ixy="0" ixz="0" iyy="0.01" iyz="0" izz="0.01" />
        </inertial>
    </link>
    <link name="pan_direk">
        <visual>
            <origin rpy="0 0 0" xyz="0 0 0" />
            <geometry>
                <box size="0.035 0.038 0.044" />
            </geometry>
            <material name="Yellow2">
                <color rgba="0.8 0.8 0 1.0" />
            </material>
        </visual>
        <inertial>
            <mass value="0.50" />
            <origin rpy="0 0 0" xyz="0 0 0" />
            <inertia ixx="0.01" ixy="0" ixz="0" iyy="0.01" iyz="0" izz="0.01" />
        </inertial>
    </link>
    <link name="tilt_direk">
        <visual>
            <origin rpy="0 -1.57 0" xyz="-0.022 0 0" />
            <geometry>
                <box size="0.005 0.005 0.044" />
            </geometry>
            <material name="Cyan1">
                <color rgba="0 0.9 0.9 1.0" />
            </material>
        </visual>
        <inertial>
            <mass value="0.20" />
            <origin rpy="0 0 0" xyz="0 0 0" />
            <inertia ixx="0.01" ixy="0" ixz="0" iyy="0.01" iyz="0" izz="0.01" />
        </inertial>
    </link>
    <link name="hokuyo_taban">
        <visual>
            <origin rpy="0 -1.57 0" xyz="0 0 0" />
            <geometry>
                <box size="0.13 0.06 0.003 " />
            </geometry>
            <material name="Yellow2">
                <color rgba="0.8 0.8 0 1.0" />
            </material>
        </visual>
        <inertial>
            <mass value="0.10" />
            <origin rpy="0 0 0" xyz="0 0 0" />
            <inertia ixx="0.01" ixy="0" ixz="0" iyy="0.01" iyz="0" izz="0.01" />
        </inertial>
    </link>
    <link name="hokuyo_link">
        <collision>
            <origin rpy="0 0 0" xyz="0 0 -0.05" />
            <geometry>
                <box size="0.1 0.1 0.08" />
            </geometry>
        </collision>
        <visual>
            <origin rpy="0 0 0" xyz="-0.035 0 0" />
            <geometry>
                <box size="0.05 0.05 0.07" />
            </geometry>
            <material name="Cyan1">
                <color rgba="0 0.9 0.9 1.0" />
            </material>
        </visual>
        <inertial>
            <mass value="1e-5" />
            <origin rpy="0 0 0" xyz="0 0 0" />
            <inertia ixx="1e-6" ixy="0" ixz="0" iyy="1e-6" iyz="0" izz="1e-6" />
        </inertial>
    </link>
    <joint name="virtual_joint" type="fixed">
        <parent link="world" />
        <child link="taban" />
        <origin rpy="0 0 0" xyz="0 0 0" />
        <dynamics damping="1.0" />
    </joint>
    <joint name="pan_joint" type="revolute">
        <parent link="taban" />
        <child link="pan_direk" />
        <origin rpy="0 0 0" xyz="0 -0.0285 0.092" />
        <dynamics damping="1.0" />
        <axis xyz="0 0 1" />
        <limit effort="10" lower="-3.1416" upper="3.1416" velocity="3" />
    </joint>
    <joint name="tilt_joint" type="revolute">
        <parent link="pan_direk" />
        <child link="tilt_direk" />
        <origin rpy="0 1.57 0" xyz="0 0 0.022" />
        <axis xyz="0 0 1" />
        <limit effort="10" lower="-0.8727" upper="0.8727" velocity="3" />
        <dynamics damping="1.0" />
    </joint>
    <joint name="hokuyo_base_joint" type="fixed">
        <parent link="tilt_direk" />
        <child link="hokuyo_taban" />
        <origin rpy="0 0 0" xyz="-0.0450 0 0" />
        <dynamics damping="1.0" />
    </joint>
    <joint name="hokuyo_joint" type="fixed">
        <origin rpy="0 -1.57 0" xyz="-0.035 0 0.075" />
        <parent link="hokuyo_taban" />
        <child link="hokuyo_link" />
        <dynamics damping="1.0" />
    </joint>
    <gazebo reference="taban">
                <material>Gazebo/Orange</material>
                <turnGravityOff>true</turnGravityOff>
        </gazebo>
        
        <gazebo reference="pan_direk">
                <material>Gazebo/Blue</material>
                <turnGravityOff>true</turnGravityOff>
                
        </gazebo>
        
        <gazebo reference="tilt_direk">
                <material>Gazebo/White</material>
                <turnGravityOff>true</turnGravityOff>
        </gazebo>
        
        <gazebo reference="hokuyo_taban">
                <material>Gazebo/Orange</material>
                <turnGravityOff>true</turnGravityOff>
        </gazebo>
    <!-- gazebo reference for hokuyo-->
    <gazebo reference="hokuyo_link">
    	<material>Gazebo/Blue</material>
        <sensor name="hokuyo_sensor" type="ray">
            <pose>0 0 0 0 0 0</pose>
            <update_rate>10</update_rate>
            <ray>
                <scan>
                    <horizontal>
                        <samples>640</samples>
                        <resolution>1</resolution>
                        <min_angle>-2.094</min_angle>
                        <max_angle>2.094</max_angle>
                    </horizontal>
                </scan>
                <range>
                    <min>0.02</min>
                    <max>4.0</max>
                    <resolution>0.00628318531</resolution>
                </range>
                <noise>
                    <type>gaussian</type>
                    <mean>0.0</mean>
                    <stddev>0.01</stddev>
                </noise>
            </ray>
            <plugin filename="libgazebo_ros_laser.so" name="body_controller">
                <topicName>hokuyo/scan</topicName>
                <frameName>hokuyo_link</frameName>
         </plugin>
        </sensor>
        <turnGravityOff>true</turnGravityOff>
    </gazebo>
    <transmission name="trans_pan_joint">
        <type>transmission_interface/SimpleTransmission</type>
        <joint name="pan_joint">
            <hardwareInterface>hardware_interface/EffortJointInterface</hardwareInterface>
        </joint>
        <actuator name="pan_joint_motor">
            <hardwareInterface>hardware_interface/EffortJointInterface</hardwareInterface>
            <mechanicalReduction>1</mechanicalReduction>
        </actuator>
    </transmission>
    <transmission name="trans_tilt_joint">
        <type>transmission_interface/SimpleTransmission</type>
        <joint name="tilt_joint">
            <hardwareInterface>hardware_interface/EffortJointInterface</hardwareInterface>
        </joint>
        <actuator name="tilt_joint_motor">
            <hardwareInterface>hardware_interface/EffortJointInterface</hardwareInterface>
            <mechanicalReduction>1</mechanicalReduction>
        </actuator>
    </transmission>
    <gazebo>
            <plugin name="gazebo_ros_control" filename="libgazebo_ros_control.so">
            </plugin>
     </gazebo>
</robot>

